<?xml version="1.0" encoding="utf-8"?>
<!-- This URDF was automatically created by SolidWorks to URDF Exporter! Originally created by Stephen Brawner (brawner@gmail.com) 
     Commit Version: 1.5.1-0-g916b5db  Build Version: 1.5.7152.31018
     For more information, please see http://wiki.ros.org/sw_urdf_exporter -->
<robot
  name="hmr">
  <link
    name="base_link">
    <inertial>
      <origin
        xyz="-0.000103296813793522 -0.0184749995894324 -0.00709986514009202"
        rpy="0 0 0" />
      <mass
        value="0.933836944447792" />
      <inertia
        ixx="0.00139201398308306"
        ixy="-2.82901658884336E-12"
        ixz="4.14929438991966E-12"
        iyy="0.00736197315629375"
        iyz="-8.0885885721078E-10"
        izz="0.00614175111526735" />
    </inertial>
    <visual>
      <origin
        xyz="0 0 0"
        rpy="0 0 0" />
      <geometry>
        <mesh
          filename="package://hmr/meshes/base_link.STL" />
      </geometry>
      <material
        name="">
        <color
          rgba="0.792156862745098 0.819607843137255 0.933333333333333 1" />
      </material>
    </visual>
    <collision>
      <origin
        xyz="0 0 0"
        rpy="0 0 0" />
      <geometry>
        <mesh
          filename="package://hmr/meshes/base_link.STL" />
      </geometry>
    </collision>
  </link>
  <link
    name="llink1">
    <inertial>
      <origin
        xyz="0.0499999851262689 -0.248500614775013 5.33671345059814E-05"
        rpy="0 0 0" />
      <mass
        value="0.509664464543895" />
      <inertia
        ixx="0.00405279295169879"
        ixy="-5.17821013423379E-16"
        ixz="-1.86028405386162E-17"
        iyy="0.000257140430774596"
        iyz="2.20410095949559E-06"
        izz="0.0041884713527824" />
    </inertial>
    <visual>
      <origin
        xyz="0 0 0"
        rpy="0 0 0" />
      <geometry>
        <mesh
          filename="package://hmr/meshes/llink1.STL" />
      </geometry>
      <material
        name="">
        <color
          rgba="0.792156862745098 0.819607843137255 0.933333333333333 1" />
      </material>
    </visual>
    <collision>
      <origin
        xyz="0 0 0"
        rpy="0 0 0" />
      <geometry>
        <mesh
          filename="package://hmr/meshes/llink1.STL" />
      </geometry>
    </collision>
  </link>
  <joint
    name="ljoint1"
    type="continuous">
    <origin
      xyz="0.120000000000052 0.0599999999998939 -0.0599999999999843"
      rpy="1.5707963267949 0 0" />
    <parent
      link="base_link" />
    <child
      link="llink1" />
    <axis
      xyz="1 0 0" />
  </joint>
  <link
    name="llink2">
    <inertial>
      <origin
        xyz="0.0500545282509017 -0.234393633663144 0.00550026352716933"
        rpy="0 0 0" />
      <mass
        value="0.442265777754145" />
      <inertia
        ixx="0.0040117979862963"
        ixy="-5.09697896497051E-16"
        ixz="-2.77164071387431E-17"
        iyy="0.000241596436981563"
        iyz="-1.10278899850188E-06"
        izz="0.00416183117175302" />
    </inertial>
    <visual>
      <origin
        xyz="0 0 0"
        rpy="0 0 0" />
      <geometry>
        <mesh
          filename="package://hmr/meshes/llink2.STL" />
      </geometry>
      <material
        name="">
        <color
          rgba="0.792156862745098 0.819607843137255 0.933333333333333 1" />
      </material>
    </visual>
    <collision>
      <origin
        xyz="0 0 0"
        rpy="0 0 0" />
      <geometry>
        <mesh
          filename="package://hmr/meshes/llink2.STL" />
      </geometry>
    </collision>
  </link>
  <joint
    name="ljoint2"
    type="continuous">
    <origin
      xyz="0 -0.499999999999959 0"
      rpy="0 0 0" />
    <parent
      link="llink1" />
    <child
      link="llink2" />
    <axis
      xyz="1 0 0" />
  </joint>
  <link
    name="llink3">
    <inertial>
      <origin
        xyz="0.0501466994062446 -0.0351041894822217 0.0405185729509365"
        rpy="0 0 0" />
      <mass
        value="0.164387087553345" />
      <inertia
        ixx="0.000390399624612182"
        ixy="6.46553823154572E-18"
        ixz="7.16521493881578E-17"
        iyy="0.000442516689346383"
        iyz="-8.18654011913839E-11"
        izz="8.27552994226968E-05" />
    </inertial>
    <visual>
      <origin
        xyz="0 0 0"
        rpy="0 0 0" />
      <geometry>
        <mesh
          filename="package://hmr/meshes/llink3.STL" />
      </geometry>
      <material
        name="">
        <color
          rgba="0.792156862745098 0.819607843137255 0.933333333333333 1" />
      </material>
    </visual>
    <collision>
      <origin
        xyz="0 0 0"
        rpy="0 0 0" />
      <geometry>
        <mesh
          filename="package://hmr/meshes/llink3.STL" />
      </geometry>
    </collision>
  </link>
  <joint
    name="ljoint3"
    type="continuous">
    <origin
      xyz="0 -0.500000000000046 0"
      rpy="0 0 0" />
    <parent
      link="llink2" />
    <child
      link="llink3" />
    <axis
      xyz="1 0 0" />
  </joint>
  <link
    name="rlink1">
    <inertial>
      <origin
        xyz="-0.0500000148736693 -0.248500614774999 5.33671345059189E-05"
        rpy="0 0 0" />
      <mass
        value="0.509664464543895" />
      <inertia
        ixx="0.00405279295169879"
        ixy="-5.17781100332924E-16"
        ixz="-1.86069004433025E-17"
        iyy="0.000257140430774596"
        iyz="2.20410095949557E-06"
        izz="0.0041884713527824" />
    </inertial>
    <visual>
      <origin
        xyz="0 0 0"
        rpy="0 0 0" />
      <geometry>
        <mesh
          filename="package://hmr/meshes/rlink1.STL" />
      </geometry>
      <material
        name="">
        <color
          rgba="0.792156862745098 0.819607843137255 0.933333333333333 1" />
      </material>
    </visual>
    <collision>
      <origin
        xyz="0 0 0"
        rpy="0 0 0" />
      <geometry>
        <mesh
          filename="package://hmr/meshes/rlink1.STL" />
      </geometry>
    </collision>
  </link>
  <joint
    name="rjoint1"
    type="continuous">
    <origin
      xyz="-0.120000000000021 0.0599999999999112 -0.0599999999999698"
      rpy="1.5707963267949 0 0" />
    <parent
      link="base_link" />
    <child
      link="rlink1" />
    <axis
      xyz="1 0 0" />
  </joint>
  <link
    name="rlink2">
    <inertial>
      <origin
        xyz="-0.049945471749016 -0.234393633663131 0.00550026352714499"
        rpy="0 0 0" />
      <mass
        value="0.442265777754145" />
      <inertia
        ixx="0.00401179798629629"
        ixy="-5.09803878440693E-16"
        ixz="-2.77168469663556E-17"
        iyy="0.000241596436981563"
        iyz="-1.10278899850179E-06"
        izz="0.00416183117175302" />
    </inertial>
    <visual>
      <origin
        xyz="0 0 0"
        rpy="0 0 0" />
      <geometry>
        <mesh
          filename="package://hmr/meshes/rlink2.STL" />
      </geometry>
      <material
        name="">
        <color
          rgba="0.792156862745098 0.819607843137255 0.933333333333333 1" />
      </material>
    </visual>
    <collision>
      <origin
        xyz="0 0 0"
        rpy="0 0 0" />
      <geometry>
        <mesh
          filename="package://hmr/meshes/rlink2.STL" />
      </geometry>
    </collision>
  </link>
  <joint
    name="rjoint2"
    type="continuous">
    <origin
      xyz="0 -0.499999999999959 0"
      rpy="0 0 0" />
    <parent
      link="rlink1" />
    <child
      link="rlink2" />
    <axis
      xyz="1 0 0" />
  </joint>
  <link
    name="rlink3">
    <inertial>
      <origin
        xyz="-0.0498532993324217 -0.0351041894822506 0.040518572950845"
        rpy="0 0 0" />
      <mass
        value="0.164387087553345" />
      <inertia
        ixx="0.000390399624612182"
        ixy="6.46331811347987E-18"
        ixz="7.16490435411506E-17"
        iyy="0.000442516689346383"
        iyz="-8.18654011935542E-11"
        izz="8.27552994226968E-05" />
    </inertial>
    <visual>
      <origin
        xyz="0 0 0"
        rpy="0 0 0" />
      <geometry>
        <mesh
          filename="package://hmr/meshes/rlink3.STL" />
      </geometry>
      <material
        name="">
        <color
          rgba="0.792156862745098 0.819607843137255 0.933333333333333 1" />
      </material>
    </visual>
    <collision>
      <origin
        xyz="0 0 0"
        rpy="0 0 0" />
      <geometry>
        <mesh
          filename="package://hmr/meshes/rlink3.STL" />
      </geometry>
    </collision>
  </link>
  <joint
    name="rjoint3"
    type="continuous">
    <origin
      xyz="0 -0.500000000000032 0"
      rpy="0 0 0" />
    <parent
      link="rlink2" />
    <child
      link="rlink3" />
    <axis
      xyz="1 0 0" />
  </joint>
</robot>